{
  "dataType": "CVE_RECORD",
  "dataVersion": "5.1",
  "cveMetadata": {
    "total_count": 2,
    "last_updated": "2025-09-25T15:46:03.510651",
    "severity_distribution": {
      "critical": 0,
      "high": 0,
      "medium": 1,
      "low": 0,
      "none": 1
    }
  },
  "cves": [
    {
      "id": "CVE-2025-10952",
      "publishedDate": "2025-09-25T15:32:05.845Z",
      "lastModifiedDate": "2025-09-25T15:32:05.845Z",
      "description": "A security flaw has been discovered in geyang ml-logger up to acf255bade5be6ad88d90735c8367b28cbe3a743. Affected by this issue is the function stream_handler of the file ml_logger/server.py of the component File Handler. Performing manipulation of the argument key results in information disclosure. The attack can be initiated remotely. The exploit has been released to the public and may be exploited. Continious delivery with rolling releases is used by this product. Therefore, no version details of affected nor updated releases are available.",
      "severity": 5.3,
      "references": [
        {
          "url": "https://vuldb.com/?id.325822",
          "type": "reference"
        },
        {
          "url": "https://vuldb.com/?ctiid.325822",
          "type": "reference"
        },
        {
          "url": "https://vuldb.com/?submit.652463",
          "type": "reference"
        },
        {
          "url": "https://github.com/geyang/ml-logger/issues/74",
          "type": "poc"
        }
      ],
      "affected": [
        {
          "vendor": "geyang",
          "product": "ml-logger",
          "versions": [
            {
              "version": "acf255bade5be6ad88d90735c8367b28cbe3a743",
              "status": "affected"
            }
          ],
          "modules": [
            "File Handler"
          ]
        }
      ],
      "problemType": [
        "Information Disclosure",
        "Improper Access Controls"
      ],
      "fix_suggestion": "无法生成修复建议"
    },
    {
      "id": "CVE-2025-55559",
      "publishedDate": "2025-09-25T00:00:00.000Z",
      "lastModifiedDate": "2025-09-25T15:32:59.969Z",
      "description": "An issue was discovered TensorFlow v2.18.0. A Denial of Service (DoS) occurs when padding is set to 'valid' in tf.keras.layers.Conv2D.",
      "severity": "N/A",
      "references": [
        {
          "url": "https://github.com/tensorflow/tensorflow/issues/84205",
          "type": "reference"
        },
        {
          "url": "https://gist.github.com/shaoyuyoung/0e7d2a586297ae9c8ed14d8706749efc",
          "type": "reference"
        }
      ],
      "affected": [
        {
          "vendor": "n/a",
          "product": "n/a",
          "versions": [
            {
              "version": "n/a",
              "status": "affected"
            }
          ]
        }
      ],
      "problemType": [
        "n/a"
      ],
      "fix_suggestion": "无法生成修复建议"
    }
  ]
}