{
  "dataType": "CVE_RECORD",
  "dataVersion": "5.1",
  "cveMetadata": {
    "total_count": 2,
    "last_updated": "2025-07-04T22:23:47.976090",
    "severity_distribution": {
      "critical": 0,
      "high": 0,
      "medium": 0,
      "low": 0,
      "none": 2
    }
  },
  "cves": [
    {
      "id": "CVE-2025-53366",
      "publishedDate": "2025-07-04T22:05:02.975Z",
      "lastModifiedDate": "2025-07-04T22:05:02.975Z",
      "description": "The MCP Python SDK, called `mcp` on PyPI, is a Python implementation of the Model Context Protocol (MCP). Prior to version 1.9.4, a validation error in the MCP SDK can cause an unhandled exception when processing malformed requests, resulting in service unavailability (500 errors) until manually restarted. Impact may vary depending on the deployment conditions, and presence of infrastructure-level resilience measures. Version 1.9.4 contains a patch for the issue.",
      "severity": "N/A",
      "references": [
        {
          "url": "https://github.com/modelcontextprotocol/python-sdk/security/advisories/GHSA-3qhf-m339-9g5v",
          "type": "reference"
        },
        {
          "url": "https://github.com/modelcontextprotocol/python-sdk/pull/822",
          "type": "reference"
        },
        {
          "url": "https://github.com/modelcontextprotocol/python-sdk/commit/29c69e6a47d0104d0afcea6ac35e7ab02fde809a",
          "type": "reference"
        }
      ],
      "affected": [
        {
          "vendor": "modelcontextprotocol",
          "product": "python-sdk",
          "versions": [
            {
              "version": "< 1.9.4",
              "status": "affected"
            }
          ]
        }
      ],
      "problemType": [
        "CWE-248: Uncaught Exception"
      ],
      "fix_suggestion": "无法生成修复建议"
    },
    {
      "id": "CVE-2025-53365",
      "publishedDate": "2025-07-04T22:03:46.893Z",
      "lastModifiedDate": "2025-07-04T22:03:46.893Z",
      "description": "The MCP Python SDK, called `mcp` on PyPI, is a Python implementation of the Model Context Protocol (MCP). Prior to version 1.10.0, if a client deliberately triggers an exception after establishing a streamable HTTP session, this can lead to an uncaught ClosedResourceError on the server side, causing the server to crash and requiring a restart to restore service. Impact may vary depending on the deployment conditions, and presence of infrastructure-level resilience measures. Version 1.10.0 contains a patch for the issue.",
      "severity": "N/A",
      "references": [
        {
          "url": "https://github.com/modelcontextprotocol/python-sdk/security/advisories/GHSA-j975-95f5-7wqh",
          "type": "reference"
        },
        {
          "url": "https://github.com/modelcontextprotocol/python-sdk/pull/967",
          "type": "reference"
        },
        {
          "url": "https://github.com/modelcontextprotocol/python-sdk/commit/7b420656de48cfdb90b39eb582e60b6d55c2f891",
          "type": "reference"
        }
      ],
      "affected": [
        {
          "vendor": "modelcontextprotocol",
          "product": "python-sdk",
          "versions": [
            {
              "version": "< 1.10.0",
              "status": "affected"
            }
          ]
        }
      ],
      "problemType": [
        "CWE-248: Uncaught Exception"
      ],
      "fix_suggestion": "无法生成修复建议"
    }
  ]
}