{
  "dataType": "CVE_RECORD",
  "dataVersion": "5.1",
  "cveMetadata": {
    "total_count": 1,
    "last_updated": "2025-03-30T16:15:43.107548",
    "severity_distribution": {
      "critical": 0,
      "high": 0,
      "medium": 0,
      "low": 1,
      "none": 0
    }
  },
  "cves": [
    {
      "id": "CVE-2025-2953",
      "publishedDate": "2025-03-30T15:31:04.853Z",
      "lastModifiedDate": "2025-03-30T15:31:04.853Z",
      "description": "A vulnerability, which was classified as problematic, has been found in PyTorch 2.6.0+cu124. Affected by this issue is the function torch.mkldnn_max_pool2d. The manipulation leads to denial of service. An attack has to be approached locally. The exploit has been disclosed to the public and may be used.",
      "severity": 3.3,
      "references": [
        {
          "url": "https://vuldb.com/?id.302006",
          "type": "reference"
        },
        {
          "url": "https://vuldb.com/?ctiid.302006",
          "type": "reference"
        },
        {
          "url": "https://vuldb.com/?submit.521279",
          "type": "reference"
        },
        {
          "url": "https://github.com/pytorch/pytorch/issues/149274",
          "type": "reference"
        },
        {
          "url": "https://github.com/pytorch/pytorch/issues/149274#issue-2923122269",
          "type": "poc"
        }
      ],
      "affected": [
        {
          "vendor": "n/a",
          "product": "PyTorch",
          "versions": [
            {
              "version": "2.6.0+cu124",
              "status": "affected"
            }
          ]
        }
      ],
      "problemType": [
        "Denial of Service"
      ],
      "fix_suggestion": "无法生成修复建议"
    }
  ]
}